Traceback (most recent call last):
  File "/opt/hostedtoolcache/Python/3.11.13/x64/lib/python3.11/site-packages/jupyter_core/utils/__init__.py", line 154, in wrapped
    asyncio.get_running_loop()
RuntimeError: no running event loop

During handling of the above exception, another exception occurred:

Traceback (most recent call last):
  File "/opt/hostedtoolcache/Python/3.11.13/x64/lib/python3.11/site-packages/jupyter_cache/executors/utils.py", line 58, in single_nb_execution
    executenb(
  File "/opt/hostedtoolcache/Python/3.11.13/x64/lib/python3.11/site-packages/nbclient/client.py", line 1319, in execute
    return NotebookClient(nb=nb, resources=resources, km=km, **kwargs).execute()
           ^^^^^^^^^^^^^^^^^^^^^^^^^^^^^^^^^^^^^^^^^^^^^^^^^^^^^^^^^^^^^^^^^^^^^
  File "/opt/hostedtoolcache/Python/3.11.13/x64/lib/python3.11/site-packages/jupyter_core/utils/__init__.py", line 158, in wrapped
    return loop.run_until_complete(inner)
           ^^^^^^^^^^^^^^^^^^^^^^^^^^^^^^
  File "/opt/hostedtoolcache/Python/3.11.13/x64/lib/python3.11/asyncio/base_events.py", line 654, in run_until_complete
    return future.result()
           ^^^^^^^^^^^^^^^
  File "/opt/hostedtoolcache/Python/3.11.13/x64/lib/python3.11/site-packages/nbclient/client.py", line 709, in async_execute
    await self.async_execute_cell(
  File "/opt/hostedtoolcache/Python/3.11.13/x64/lib/python3.11/site-packages/nbclient/client.py", line 1062, in async_execute_cell
    await self._check_raise_for_error(cell, cell_index, exec_reply)
  File "/opt/hostedtoolcache/Python/3.11.13/x64/lib/python3.11/site-packages/nbclient/client.py", line 918, in _check_raise_for_error
    raise CellExecutionError.from_cell_and_msg(cell, exec_reply_content)
nbclient.exceptions.CellExecutionError: An error occurred while executing the following cell:
------------------
import dask
import dask.dataframe as dd
import dask.bag as db
from dask.distributed import Client, as_completed, progress
from dask.delayed import delayed
import pandas as pd
import numpy as np
import time
import os
import hashlib
from pathlib import Path
import logging
from functools import wraps
import json
------------------


[31m---------------------------------------------------------------------------[39m
[31mModuleNotFoundError[39m                       Traceback (most recent call last)
[36mFile [39m[32m/opt/hostedtoolcache/Python/3.11.13/x64/lib/python3.11/site-packages/dask/distributed.py:13[39m
[32m     12[39m [38;5;28;01mtry[39;00m:
[32m---> [39m[32m13[39m     [38;5;28;01mfrom[39;00m[38;5;250m [39m[34;01mdistributed[39;00m[38;5;250m [39m[38;5;28;01mimport[39;00m *
[32m     14[39m [38;5;28;01mexcept[39;00m [38;5;167;01mImportError[39;00m [38;5;28;01mas[39;00m e:

[31mModuleNotFoundError[39m: No module named 'distributed'

The above exception was the direct cause of the following exception:

[31mImportError[39m                               Traceback (most recent call last)
[36mCell[39m[36m [39m[32mIn[1][39m[32m, line 4[39m
[32m      2[39m [38;5;28;01mimport[39;00m[38;5;250m [39m[34;01mdask[39;00m[34;01m.[39;00m[34;01mdataframe[39;00m[38;5;250m [39m[38;5;28;01mas[39;00m[38;5;250m [39m[34;01mdd[39;00m
[32m      3[39m [38;5;28;01mimport[39;00m[38;5;250m [39m[34;01mdask[39;00m[34;01m.[39;00m[34;01mbag[39;00m[38;5;250m [39m[38;5;28;01mas[39;00m[38;5;250m [39m[34;01mdb[39;00m
[32m----> [39m[32m4[39m [38;5;28;01mfrom[39;00m[38;5;250m [39m[34;01mdask[39;00m[34;01m.[39;00m[34;01mdistributed[39;00m[38;5;250m [39m[38;5;28;01mimport[39;00m Client, as_completed, progress
[32m      5[39m [38;5;28;01mfrom[39;00m[38;5;250m [39m[34;01mdask[39;00m[34;01m.[39;00m[34;01mdelayed[39;00m[38;5;250m [39m[38;5;28;01mimport[39;00m delayed
[32m      6[39m [38;5;28;01mimport[39;00m[38;5;250m [39m[34;01mpandas[39;00m[38;5;250m [39m[38;5;28;01mas[39;00m[38;5;250m [39m[34;01mpd[39;00m

[36mFile [39m[32m/opt/hostedtoolcache/Python/3.11.13/x64/lib/python3.11/site-packages/dask/distributed.py:16[39m
[32m     14[39m [38;5;28;01mexcept[39;00m [38;5;167;01mImportError[39;00m [38;5;28;01mas[39;00m e:
[32m     15[39m     [38;5;28;01mif[39;00m e.msg == [33m"[39m[33mNo module named [39m[33m'[39m[33mdistributed[39m[33m'[39m[33m"[39m:
[32m---> [39m[32m16[39m         [38;5;28;01mraise[39;00m [38;5;167;01mImportError[39;00m(_import_error_message) [38;5;28;01mfrom[39;00m[38;5;250m [39m[34;01me[39;00m
[32m     17[39m     [38;5;28;01melse[39;00m:
[32m     18[39m         [38;5;28;01mraise[39;00m

[31mImportError[39m: dask.distributed is not installed.

Please either conda or pip install distributed:

  conda install dask distributed             # either conda install
  python -m pip install "dask[distributed]" --upgrade    # or pip install

